Traceback (most recent call last):
  File "/home/dongorae/.local/lib/python3.10/site-packages/jupyter_cache/executors/utils.py", line 51, in single_nb_execution
    executenb(
  File "/home/dongorae/.local/lib/python3.10/site-packages/nbclient/client.py", line 1204, in execute
    return NotebookClient(nb=nb, resources=resources, km=km, **kwargs).execute()
  File "/home/dongorae/.local/lib/python3.10/site-packages/nbclient/util.py", line 84, in wrapped
    return just_run(coro(*args, **kwargs))
  File "/home/dongorae/.local/lib/python3.10/site-packages/nbclient/util.py", line 62, in just_run
    return loop.run_until_complete(coro)
  File "/usr/lib/python3.10/asyncio/base_events.py", line 646, in run_until_complete
    return future.result()
  File "/home/dongorae/.local/lib/python3.10/site-packages/nbclient/client.py", line 663, in async_execute
    await self.async_execute_cell(
  File "/home/dongorae/.local/lib/python3.10/site-packages/nbclient/client.py", line 965, in async_execute_cell
    await self._check_raise_for_error(cell, cell_index, exec_reply)
  File "/home/dongorae/.local/lib/python3.10/site-packages/nbclient/client.py", line 862, in _check_raise_for_error
    raise CellExecutionError.from_cell_and_msg(cell, exec_reply_content)
nbclient.exceptions.CellExecutionError: An error occurred while executing the following cell:
------------------
# iteration.csv 파일이 존재하는 폴더 경로 지정
simtrace_path = "/content/gdrive/MyDrive/deepracer-lecture-open-data/download_logs_sample/test-training-job/sim-trace/training/training-simtrace" 

# 파일 목록 가져오기
file_list = os.listdir(simtrace_path)

# 전처리한 데이터 프레임을 담을 리스트
df_list = []

# 전처리
for target_file in file_list : 
  target_iteration = int(target_file.split('-')[0])
  target_path = os.path.join(simtrace_path, target_file)

  with open(target_path) as f :
      csv_readlines = f.readlines()

  columns = ['iteration'] + csv_readlines[0].replace('\n','').split(',')
  data = []
  for line_text in csv_readlines[1:] :
    row = eval('[' + line_text.replace('\n','').replace('prepare', "'prepare'").replace('in_progress', "'in_progress'").replace('off_track', "'off_track'").replace('crashed',"'off_track'").replace('lap_complete',"'lap_complete'") + ']')
    data.append([target_iteration] + row)

  df_target = pd.DataFrame(columns = columns, data = data)
  df_list.append(df_target)

# 전처리 된 데이터프레임 병합
df_data = pd.concat(df_list).reset_index(drop=True)

df_data
------------------

[0;31m---------------------------------------------------------------------------[0m
[0;31mFileNotFoundError[0m                         Traceback (most recent call last)
Cell [0;32mIn[3], line 5[0m
[1;32m      2[0m simtrace_path [38;5;241m=[39m [38;5;124m"[39m[38;5;124m/content/gdrive/MyDrive/deepracer-lecture-open-data/download_logs_sample/test-training-job/sim-trace/training/training-simtrace[39m[38;5;124m"[39m 
[1;32m      4[0m [38;5;66;03m# 파일 목록 가져오기[39;00m
[0;32m----> 5[0m file_list [38;5;241m=[39m [43mos[49m[38;5;241;43m.[39;49m[43mlistdir[49m[43m([49m[43msimtrace_path[49m[43m)[49m
[1;32m      7[0m [38;5;66;03m# 전처리한 데이터 프레임을 담을 리스트[39;00m
[1;32m      8[0m df_list [38;5;241m=[39m []

[0;31mFileNotFoundError[0m: [Errno 2] No such file or directory: '/content/gdrive/MyDrive/deepracer-lecture-open-data/download_logs_sample/test-training-job/sim-trace/training/training-simtrace'
FileNotFoundError: [Errno 2] No such file or directory: '/content/gdrive/MyDrive/deepracer-lecture-open-data/download_logs_sample/test-training-job/sim-trace/training/training-simtrace'

