Traceback (most recent call last):
  File "/home/dongorae/.local/lib/python3.10/site-packages/jupyter_cache/executors/utils.py", line 51, in single_nb_execution
    executenb(
  File "/home/dongorae/.local/lib/python3.10/site-packages/nbclient/client.py", line 1204, in execute
    return NotebookClient(nb=nb, resources=resources, km=km, **kwargs).execute()
  File "/home/dongorae/.local/lib/python3.10/site-packages/nbclient/util.py", line 84, in wrapped
    return just_run(coro(*args, **kwargs))
  File "/home/dongorae/.local/lib/python3.10/site-packages/nbclient/util.py", line 62, in just_run
    return loop.run_until_complete(coro)
  File "/usr/lib/python3.10/asyncio/base_events.py", line 646, in run_until_complete
    return future.result()
  File "/home/dongorae/.local/lib/python3.10/site-packages/nbclient/client.py", line 663, in async_execute
    await self.async_execute_cell(
  File "/home/dongorae/.local/lib/python3.10/site-packages/nbclient/client.py", line 965, in async_execute_cell
    await self._check_raise_for_error(cell, cell_index, exec_reply)
  File "/home/dongorae/.local/lib/python3.10/site-packages/nbclient/client.py", line 862, in _check_raise_for_error
    raise CellExecutionError.from_cell_and_msg(cell, exec_reply_content)
nbclient.exceptions.CellExecutionError: An error occurred while executing the following cell:
------------------
# 리스트를 생성합니다.
x = [10,20,30,40]

# 범위를 벗어난 인덱스로 리스트의 원소를 호출하면 에러가 발생합니다.
print(x[4])
------------------

[0;31m---------------------------------------------------------------------------[0m
[0;31mIndexError[0m                                Traceback (most recent call last)
Cell [0;32mIn[14], line 5[0m
[1;32m      2[0m x [38;5;241m=[39m [[38;5;241m10[39m,[38;5;241m20[39m,[38;5;241m30[39m,[38;5;241m40[39m]
[1;32m      4[0m [38;5;66;03m# 범위를 벗어난 인덱스로 리스트의 원소를 호출하면 에러가 발생합니다.[39;00m
[0;32m----> 5[0m [38;5;28mprint[39m([43mx[49m[43m[[49m[38;5;241;43m4[39;49m[43m][49m)

[0;31mIndexError[0m: list index out of range
IndexError: list index out of range

