Traceback (most recent call last):
  File "/home/dongorae/.local/lib/python3.10/site-packages/jupyter_cache/executors/utils.py", line 51, in single_nb_execution
    executenb(
  File "/home/dongorae/.local/lib/python3.10/site-packages/nbclient/client.py", line 1204, in execute
    return NotebookClient(nb=nb, resources=resources, km=km, **kwargs).execute()
  File "/home/dongorae/.local/lib/python3.10/site-packages/nbclient/util.py", line 84, in wrapped
    return just_run(coro(*args, **kwargs))
  File "/home/dongorae/.local/lib/python3.10/site-packages/nbclient/util.py", line 62, in just_run
    return loop.run_until_complete(coro)
  File "/usr/lib/python3.10/asyncio/base_events.py", line 646, in run_until_complete
    return future.result()
  File "/home/dongorae/.local/lib/python3.10/site-packages/nbclient/client.py", line 663, in async_execute
    await self.async_execute_cell(
  File "/home/dongorae/.local/lib/python3.10/site-packages/nbclient/client.py", line 965, in async_execute_cell
    await self._check_raise_for_error(cell, cell_index, exec_reply)
  File "/home/dongorae/.local/lib/python3.10/site-packages/nbclient/client.py", line 862, in _check_raise_for_error
    raise CellExecutionError.from_cell_and_msg(cell, exec_reply_content)
nbclient.exceptions.CellExecutionError: An error occurred while executing the following cell:
------------------
# 지역 변수를 함수 외부에서 호출하면 에러가 납니다.

def g(x) :
    local_variable = x**2
    return local_variable

print(g(3))
print(local_variable)
------------------

[0;31m---------------------------------------------------------------------------[0m
[0;31mNameError[0m                                 Traceback (most recent call last)
Cell [0;32mIn[7], line 8[0m
[1;32m      5[0m     [38;5;28;01mreturn[39;00m local_variable
[1;32m      7[0m [38;5;28mprint[39m(g([38;5;241m3[39m))
[0;32m----> 8[0m [38;5;28mprint[39m([43mlocal_variable[49m)

[0;31mNameError[0m: name 'local_variable' is not defined
NameError: name 'local_variable' is not defined

